Workbook

Sheet Raw_data
A1: External | B1: Mat | C1: Url | D1: Full name | E1: Email | F1: Entry date | G1: Work experience since | H1: Total engagements | I1: Engagements with invalid dates | J1: Ongoing engagements | K1: Oldest ongoing engagement start date | L1: Last finished engagement start date | M1: Last finished engagement end date | N1: Is profile photo missing | O1: Months since entry baseline | P1: Absolute months since entry | Q1: Weighted months since entry | R1: Absolute missing months since entry | S1: Weighted missing months since entry | T1: Absolute coverage ratio since entry | U1: Weighted coverage ratio since entry | V1: Months before entry baseline | W1: Absolute months before entry | X1: Weighted months before entry | Y1: Absolute missing months before entry | Z1: Weighted missing months before entry | AA1: Absolute coverage ratio before entry | AB1: Weighted coverage ratio before entry | AC1: Is entry date missing | AD1: Is work experience since missing | AE1: Is work experience since after entry date | AF1: Is available | AG1: Available from | AH1: Available to | AI1: Is willing to travel | AJ1: Available days per week | AK1: Availability comment | AL1: Department | AM1: Team | AN1: Unit | AO1: Legal entity | AP1: Location | AQ1: Lead
A2: 2221 | B2: 594F6B | C2: https://app.matchical.com/Consulting/ConsultantDetail?ConsultantId=81c0d4c6-ad00-4890-a981-23b344efe2f7 | D2: Abdulsalam Ginebas | E2: abdulsalam.ginebas@bridging-it.de | F2: 43282 | G2: 40330 | H2: 9 | I2: 0 | J2: 0 | L2: 45748 | M2: 46021 | N2: FALSE | O2: 92 | P2: 171 | Q2: 91 | R2: =ROUND(O2-P2,2) | S2: =ROUND(O2-Q2,2) | T2: =IFERROR(P2/O2,"") | U2: =IFERROR(Q2/O2,"") | V2: 97 | W2: 29 | X2: 29 | Y2: =ROUND(V2-W2,2) | Z2: =ROUND(V2-X2,2) | AA2: =IFERROR(W2/V2,"") | AB2: =IFERROR(X2/V2,"") | AC2: FALSE | AD2: FALSE | AE2: FALSE | AF2: No | AI2: FALSE | AJ2: 0 | AK2: - Software Architect Focus on international projects in the context of AWS, Analytics, Security, Mobility | AL2: ES Enterprise Solutions (Gina H.) | AM2: DA Data & AI Solutions (Ralf Fi.) | AN2: PA Platform & Application Solutions (Thomas K.) | AO2: bridgingIT GmbH | AP2: Stuttgart | AQ2: Ralf Fischer
A3: 1208 | B3: C085E2 | C3: https://app.matchical.com/Consulting/ConsultantDetail?ConsultantId=0d3173bb-0ead-4fb6-8eab-b9083e90c3e1 | D3: Adam Birkstedt | E3: adam.birkstedt@bridging-it.de | F3: 41183 | G3: 41187 | H3: 11 | I3: 0 | J3: 2 | K3: 41760 | L3: 41334 | M3: 43829 | N3: FALSE | O3: 161 | P3: 583.97 | Q3: 160.79 | R3: =ROUND(O3-P3,2) | S3: =ROUND(O3-Q3,2) | T3: =IFERROR(P3/O3,"") | U3: =IFERROR(Q3/O3,"") | V3: 0 | W3: 0 | X3: 0 | Y3: =ROUND(V3-W3,2) | Z3: =ROUND(V3-X3,2) | AA3: =IFERROR(W3/V3,"") | AB3: =IFERROR(X3/V3,"") | AC3: FALSE | AD3: FALSE | AE3: TRUE | AF3: No | AI3: FALSE | AJ3: 0 | AL3: A&SE Analytics & Software Engineering (Philip R.) | AM3: FH Fullstack Heroes (Lars P.) | AN3: FUN Fullstack Ninjas (Stefan Z.) | AO3: bridgingIT GmbH | AP3: Mannheim | AQ3: Lars Preschke
A4: 10058 | B4: 201440 | C4: https://app.matchical.com/Consulting/ConsultantDetail?ConsultantId=bdfa7b90-c6cb-4737-938e-acb11e9d5c1f | D4: Adrian Josef Krolczyk | E4: adrian.krolczyk@fastahead.com | F4: 44958 | G4: 39052 | H4: 9 | I4: 0 | J4: 0 | L4: 45761 | M4: 46022 | N4: FALSE | O4: 37 | P4: 59 | Q4: 35 | R4: =ROUND(O4-P4,2) | S4: =ROUND(O4-Q4,2) | T4: =IFERROR(P4/O4,"") | U4: =IFERROR(Q4/O4,"") | V4: 194 | W4: 97 | X4: 97 | Y4: =ROUND(V4-W4,2) | Z4: =ROUND(V4-X4,2) | AA4: =IFERROR(W4/V4,"") | AB4: =IFERROR(X4/V4,"") | AC4: FALSE | AD4: FALSE | AE4: FALSE | AF4: No | AI4: TRUE | AJ4: 0 | AK4: The project end date is fixed with the handover of activities. In the meantime, another project can already start (ramp-up). | AL4: ORG fastahead GmbH & Co. KG | AM4: Business-driven Architectures (Dr. C. Gitte) | AN4: fah Tim Thierfelder | AO4: fastahead GmbH & Co. KG | AP4: Berlin | AQ4: Christian Gitte
A5: 3249 | B5: D167A3 | C5: https://app.matchical.com/Consulting/ConsultantDetail?ConsultantId=a0d832f3-d590-4d40-ade1-db1aba8fbea2 | D5: Adrian Knorr | E5: adrian.knorr@bridging-it.de | F5: 44669 | G5: 41518 | H5: 8 | I5: 0 | J5: 0 | L5: 45658 | M5: 46022 | N5: FALSE | O5: 46 | P5: 53 | Q5: 42 | R5: =ROUND(O5-P5,2) | S5: =ROUND(O5-Q5,2) | T5: =IFERROR(P5/O5,"") | U5: =IFERROR(Q5/O5,"") | V5: 104 | W5: 118 | X5: 90 | Y5: =ROUND(V5-W5,2) | Z5: =ROUND(V5-X5,2) | AA5: =IFERROR(W5/V5,"") | AB5: =IFERROR(X5/V5,"") | AC5: FALSE | AD5: FALSE | AE5: FALSE | AF5: No | AI5: TRUE | AJ5: 0 | AK5: Adrian is an experienced business analyst and product manager with experience in UI/UX and AI. Adrian is actively seeking a project in the AI field and also brings the necessary knowledge for it. | AL5: ORG bIT | AM5: BAPO - BA and Product Ownership (Edgar K.) | AN5: ABC Analysing Business & Collaboration (Edgar K.) | AO5: bridgingIT GmbH | AP5: Frankfurt | AQ5: Edgar Kauz
A6: 8663 | B6: 87292E | C6: https://app.matchical.com/Consulting/ConsultantDetail?ConsultantId=8afb61cd-046f-4995-b171-7cfdf8099644 | D6: Adrian Roser | E6: adrian.roser@crafting-it.de | F6: 44197 | G6: 43344 | H6: 23 | I6: 0 | J6: 0 | L6: 45658 | M6: 45838 | N6: FALSE | O6: 62 | P6: 257.97 | Q6: 54.99 | R6: =ROUND(O6-P6,2) | S6: =ROUND(O6-Q6,2) | T6: =IFERROR(P6/O6,"") | U6: =IFERROR(Q6/O6,"") | V6: 28 | W6: 0.03 | X6: 0.01 | Y6: =ROUND(V6-W6,2) | Z6: =ROUND(V6-X6,2) | AA6: =IFERROR(W6/V6,"") | AB6: =IFERROR(X6/V6,"") | AC6: FALSE | AD6: FALSE | AE6: FALSE | AF6: No | AI6: TRUE | AJ6: 0 | AL6: ORG cIT | AM6: cIT AMS / GIS Services (Michael B.) | AN6: cIT Service Delivery Magdeburg (Steffen A.) | AO6: craftingIT GmbH | AP6: Karlsruhe | AQ6: Michael Buchter
A7: 2064 | B7: F8F6B0 | C7: https://app.matchical.com/Consulting/ConsultantDetail?ConsultantId=c20648d7-9db2-4d22-bcb1-28e927b563da | D7: Afshan Tabbasum | E7: afshan.tabbasum@bridging-it.de | F7: 41275 | G7: 39934 | H7: 51 | I7: 0 | J7: 3 | K7: 44347 | L7: 45839 | M7: 46022 | N7: FALSE | O7: 158 | P7: 557 | Q7: 157.77 | R7: =ROUND(O7-P7,2) | S7: =ROUND(O7-Q7,2) | T7: =IFERROR(P7/O7,"") | U7: =IFERROR(Q7/O7,"") | V7: 44 | W7: 57.01 | X7: 38.01 | Y7: =ROUND(V7-W7,2) | Z7: =ROUND(V7-X7,2) | AA7: =IFERROR(W7/V7,"") | AB7: =IFERROR(X7/V7,"") | AC7: FALSE | AD7: FALSE | AE7: FALSE | AF7: No | AI7: FALSE | AJ7: 0 | AK7: * Microsoft 365 Power Platform, Power Apps and Power Automate * Microsoft Adaptive Cards Development * K2 Workflow Development | AL7: ES Enterprise Solutions (Gina H.) | AM7: PE Platform Engineering (Thomas K.) | AN7: PA Platform & Application Solutions (Thomas K.) | AO7: bridgingIT GmbH | AP7: Stuttgart | AQ7: Thomas Kiri
A8: 10052 | B8: 48C410 | C8: https://app.matchical.com/Consulting/ConsultantDetail?ConsultantId=1b3c0d4f-857b-47c6-907f-57d01862cd86 | D8: Ahmad Kamhieh | E8: ahmad.kamhieh@bridging-it.de | F8: 44958 | G8: 44409 | H8: 14 | I8: 0 | J8: 0 | L8: 45414 | M8: 45504 | N8: FALSE | O8: 37 | P8: 54.64 | Q8: 19.32 | R8: =ROUND(O8-P8,2) | S8: =ROUND(O8-Q8,2) | T8: =IFERROR(P8/O8,"") | U8: =IFERROR(Q8/O8,"") | V8: 18 | W8: 15.36 | X8: 12.68 | Y8: =ROUND(V8-W8,2) | Z8: =ROUND(V8-X8,2) | AA8: =IFERROR(W8/V8,"") | AB8: =IFERROR(X8/V8,"") | AC8: FALSE | AD8: FALSE | AE8: FALSE | AF8: Yes | AG8: 46174 | AI8: FALSE | AJ8: 1.82 | AK8: Fullstack (.NET and Angular) Developer Leads at: TKE, SPIE JSS, KVNO | AL8: ES Enterprise Solutions (Gina H.) | AM8: IEM .Net II (Aleksandar B.) | AN8: IEJ Individualentwicklung JAVA (Dominik S.) | AO8: bridgingIT GmbH | AP8: Stuttgart | AQ8: Aleksandar Blagojevic
A9: 10430 | B9: 3A0086 | C9: https://app.matchical.com/Consulting/ConsultantDetail?ConsultantId=ec49d130-9afa-4329-883f-4e918e6e1bfe | D9: Ahmad Osman | E9: ahmad.osman@bridging-it.de | F9: 46054 | G9: 41275 | H9: 8 | I9: 0 | J9: 0 | L9: 44926 | M9: 46052 | N9: FALSE | O9: 1 | P9: 0 | Q9: 0 | R9: =ROUND(O9-P9,2) | S9: =ROUND(O9-Q9,2) | T9: =IFERROR(P9/O9,"") | U9: =IFERROR(Q9/O9,"") | V9: 157 | W9: 183.92 | X9: 154.94 | Y9: =ROUND(V9-W9,2) | Z9: =ROUND(V9-X9,2) | AA9: =IFERROR(W9/V9,"") | AB9: =IFERROR(X9/V9,"") | AC9: FALSE | AD9: FALSE | AE9: FALSE | AF9: Yes | AG9: 46062 | AI9: TRUE | AJ9: 5 | AL9: IT - Information Technology (HH) | AM9: CRM I - Platform Solutions & CRM (Fortunato D. D.) | AN9: BAA HH (Torben H.) | AO9: bridgingIT GmbH | AP9: Hamburg | AQ9: Fortunato Di Donato
A10: 10044 | B10: 2CE8C5 | C10: https://app.matchical.com/Consulting/ConsultantDetail?ConsultantId=609d0e65-d3d2-486c-a4de-ad31eb1e1a1d | D10: Akash Saraswat | E10: akash.saraswat@bridging-it.de | F10: 44986 | G10: 43831 | H10: 10 | I10: 0 | J10: 2 | K10: 45292 | L10: 45658 | M10: 46022 | N10: FALSE | O10: 36 | P10: 105 | Q10: 35 | R10: =ROUND(O10-P10,2) | S10: =ROUND(O10-Q10,2) | T10: =IFERROR(P10/O10,"") | U10: =IFERROR(Q10/O10,"") | V10: 38 | W10: 72.97 | X10: 37.95 | Y10: =ROUND(V10-W10,2) | Z10: =ROUND(V10-X10,2) | AA10: =IFERROR(W10/V10,"") | AB10: =IFERROR(X10/V10,"") | AC10: FALSE | AD10: FALSE | AE10: FALSE | AF10: No | AI10: TRUE | AJ10: 0 | AK10: Experience with process digitization and low-code, as well as BI (primarily SAP Analytics Cloud, and Power BI), dashboard design, and process design. | AL10: DO Digital Organizations (Michael H.) | AM10: PD Process Digitalization II (Ralf Fr.) | AN10: DP Digital Processes (Hermann L.) | AO10: bridgingIT GmbH | AP10: Stuttgart | AQ10: Ralf Frotscher
A11: 2136 | B11: 75F54F | C11: https://app.matchical.com/Consulting/ConsultantDetail?ConsultantId=25ffe9cd-2779-4db8-b1fc-6e8cb3ac0a50 | D11: Aleksandar Blagojevic | E11: aleksandar.blagojevic@bridging-it.de | F11: 42401 | G11: 38412 | H11: 26 | I11: 0 | J11: 0 | L11: 44787 | M11: 45077 | N11: FALSE | O11: 121 | P11: 167 | Q11: 88 | R11: =ROUND(O11-P11,2) | S11: =ROUND(O11-Q11,2) | T11: =IFERROR(P11/O11,"") | U11: =IFERROR(Q11/O11,"") | V11: 131 | W11: 117 | X11: 76 | Y11: =ROUND(V11-W11,2) | Z11: =ROUND(V11-X11,2) | AA11: =IFERROR(W11/V11,"") | AB11: =IFERROR(X11/V11,"") | AC11: FALSE | AD11: FALSE | AE11: FALSE | AF11: No | AI11: FALSE | AJ11: 5 | AL11: ES Enterprise Solutions (Gina H.) | AM11: IEM .Net II (Aleksandar B.) | AN11: IEJ Individualentwicklung JAVA (Dominik S.) | AO11: bridgingIT GmbH | AP11: Stuttgart | AQ11: Dominik Schadow
A12: 10299 | B12: 8734EF | C12: https://app.matchical.com/Consulting/ConsultantDetail?ConsultantId=ac32b51f-8c73-497e-857a-f2829db9398f | D12: Aleksandar Bozic | E12: aleksandar.bozic@bridging-it.de | F12: 45536 | G12: 44562 | H12: 7 | I12: 0 | J12: 0 | L12: 45607 | M12: 46022 | N12: FALSE | O12: 18 | P12: 14 | Q12: 14 | R12: =ROUND(O12-P12,2) | S12: =ROUND(O12-Q12,2) | T12: =IFERROR(P12/O12,"") | U12: =IFERROR(Q12/O12,"") | V12: 32 | W12: 95 | X12: 31 | Y12: =ROUND(V12-W12,2) | Z12: =ROUND(V12-X12,2) | AA12: =IFERROR(W12/V12,"") | AB12: =IFERROR(X12/V12,"") | AC12: FALSE | AD12: FALSE | AE12: FALSE | AF12: Yes | AG12: 46143 | AI12: TRUE | AJ12: 5 | AL12: IT - Information Technology (Sebastian L.) | AM12: P&P - Processes & Platforms (Bernd O.) | AN12: P&DE - Platforms & Digital Ecosystems (David S.) | AO12: bridgingIT GmbH | AP12: Mannheim | AQ12: Bernd Opitz
A13: 10273 | B13: A7182D | C13: https://app.matchical.com/Consulting/ConsultantDetail?ConsultantId=e17d68c8-49df-4439-a5f1-5da226881413 | D13: Alex Befort | E13: alex.befort@bridging-it.de | F13: 45352 | G13: 42552 | H13: 9 | I13: 0 | J13: 0 | L13: 45404 | M13: 46021 | N13: FALSE | O13: 24 | P13: 21.67 | Q13: 21.67 | R13: =ROUND(O13-P13,2) | S13: =ROUND(O13-Q13,2) | T13: =IFERROR(P13/O13,"") | U13: =IFERROR(Q13/O13,"") | V13: 92 | W13: 94.97 | X13: 83.97 | Y13: =ROUND(V13-W13,2) | Z13: =ROUND(V13-X13,2) | AA13: =IFERROR(W13/V13,"") | AB13: =IFERROR(X13/V13,"") | AC13: FALSE | AD13: FALSE | AE13: FALSE | AF13: No | AI13: TRUE | AJ13: 0 | AL13: ORG bIT | AM13: SE Software Engineering Frankfurt (Sebastian F.) | AN13: ES Enterprise Solutions (Dominik H.) | AO13: bridgingIT GmbH | AP13: Frankfurt | AQ13: Sebastian Fischer
A14: 2311 | B14: 043588 | C14: https://app.matchical.com/Consulting/ConsultantDetail?ConsultantId=01ccef19-031b-4be5-8f8e-7fbfaece0176 | D14: Alexander Bloch | E14: alexander.bloch@bridging-it.de | F14: 44682 | G14: 44682 | H14: 15 | I14: 0 | J14: 2 | K14: 44682 | L14: 45658 | M14: 46052 | N14: FALSE | O14: 46 | P14: 177 | Q14: 45.83 | R14: =ROUND(O14-P14,2) | S14: =ROUND(O14-Q14,2) | T14: =IFERROR(P14/O14,"") | U14: =IFERROR(Q14/O14,"") | V14: 0 | W14: 0 | X14: 0 | Y14: =ROUND(V14-W14,2) | Z14: =ROUND(V14-X14,2) | AA14: =IFERROR(W14/V14,"") | AB14: =IFERROR(X14/V14,"") | AC14: FALSE | AD14: FALSE | AE14: FALSE | AF14: No | AI14: TRUE | AJ14: 0 | AK14: Focus areas in IT security, cloud security, and cloud technologies. | AL14: IT Information Technology (Hauke G.) | AM14: ITS IT Security (Erhan N.) | AN14: GRC IT-GRC (Erhan N.) | AO14: bridgingIT GmbH | AP14: Stuttgart | AQ14: Erhan Nurdogan
A15: 10413 | B15: 45C492 | C15: https://app.matchical.com/Consulting/ConsultantDetail?ConsultantId=221f5fc7-f67a-43f7-85e5-7bf6f590c1d0 | D15: Alexander Celik | E15: alexander.celik@bridging-it.de | F15: 46023 | G15: 39661 | H15: 2 | I15: 0 | J15: 0 | L15: 45747 | M15: 46021 | N15: FALSE | O15: 2 | P15: 0 | Q15: 0 | R15: =ROUND(O15-P15,2) | S15: =ROUND(O15-Q15,2) | T15: =IFERROR(P15/O15,"") | U15: =IFERROR(Q15/O15,"") | V15: 209 | W15: 42 | X15: 42 | Y15: =ROUND(V15-W15,2) | Z15: =ROUND(V15-X15,2) | AA15: =IFERROR(W15/V15,"") | AB15: =IFERROR(X15/V15,"") | AC15: FALSE | AD15: FALSE | AE15: FALSE | AF15: Yes | AG15: 46113 | AI15: FALSE | AJ15: 5 | AL15: IT - Information Technology (HH) | AM15: TM - Transition Management (Christoph W.) | AN15: MWT HH (Udo P.) | AO15: bridgingIT GmbH | AP15: Hamburg | AQ15: Christoph Wudtke
A16: 3220 | B16: 040D65 | C16: https://app.matchical.com/Consulting/ConsultantDetail?ConsultantId=5353bccf-0e19-4f9f-b1db-1278b9ae1cbf | D16: Alexander Galesky | E16: alexander.galesky@bridging-it.de | F16: 44242 | G16: 33848 | H16: 3 | I16: 0 | J16: 1 | K16: 43466 | L16: 43709 | M16: 43922 | N16: FALSE | O16: 60 | P16: 59.74 | Q16: 57.28 | R16: =ROUND(O16-P16,2) | S16: =ROUND(O16-Q16,2) | T16: =IFERROR(P16/O16,"") | U16: =IFERROR(Q16/O16,"") | V16: 341 | W16: 35.26 | X16: 30.72 | Y16: =ROUND(V16-W16,2) | Z16: =ROUND(V16-X16,2) | AA16: =IFERROR(W16/V16,"") | AB16: =IFERROR(X16/V16,"") | AC16: FALSE | AD16: FALSE | AE16: FALSE | AF16: No | AG16: 44317 | AH16: 44561 | AI16: FALSE | AJ16: 5 | AK16: Alex's topics: GDPR, PL, DBs, Siebel CRM, Automic Automation ONE, OneTrust | AL16: ORG bIT | AM16: Life Science Solutions FFM1 (Holger B.) | AN16: CC Life Science Solutions (Sabine S.) | AO16: bridgingIT GmbH | AP16: Frankfurt | AQ16: Holger Bohlen
A17: 8241 | B17: 46AECD | C17: https://app.matchical.com/Consulting/ConsultantDetail?ConsultantId=4f3787e9-29ce-4cd4-9884-d9a6748620a3 | D17: Alexander Jende | E17: alexander.jende@crafting-it.de | F17: 42856 | G17: 36069 | H17: 2 | I17: 0 | J17: 0 | L17: 45292 | M17: 45657 | N17: FALSE | O17: 106 | P17: 22 | Q17: 22 | R17: =ROUND(O17-P17,2) | S17: =ROUND(O17-Q17,2) | T17: =IFERROR(P17/O17,"") | U17: =IFERROR(Q17/O17,"") | V17: 223 | W17: 0 | X17: 0 | Y17: =ROUND(V17-W17,2) | Z17: =ROUND(V17-X17,2) | AA17: =IFERROR(W17/V17,"") | AB17: =IFERROR(X17/V17,"") | AC17: FALSE | AD17: FALSE | AE17: FALSE | AF17: No | AI17: TRUE | AJ17: 0 | AL17: ORG cIT 2 | AM17: LS Lokation Magdeburg | AN17: LS Lokation Magdeburg (Alexander J.) | AO17: craftingIT GmbH | AP17: Magdeburg | AQ17: Christian Kobl
A18: 10390 | B18: 4267DA | C18: https://app.matchical.com/Consulting/ConsultantDetail?ConsultantId=7ce6750c-3db0-4359-b087-9566472115e4 | D18: Alexander Käther | E18: alexander.kaether@bridging-it.de | F18: 45901 | H18: 3 | I18: 0 | J18: 0 | L18: 45412 | M18: 45746 | N18: FALSE | O18: 6 | P18: 0 | Q18: 0 | R18: =ROUND(O18-P18,2) | S18: =ROUND(O18-Q18,2) | T18: =IFERROR(P18/O18,"") | U18: =IFERROR(Q18/O18,"") | V18: 1508 | W18: 58 | X18: 58 | Y18: =ROUND(V18-W18,2) | Z18: =ROUND(V18-X18,2) | AA18: =IFERROR(W18/V18,"") | AB18: =IFERROR(X18/V18,"") | AC18: FALSE | AD18: FALSE | AE18: FALSE | AF18: Yes | AG18: 46143 | AI18: TRUE | AJ18: 1.59 | AK18: Experienced IT project manager and Product Owner with a strong focus on hands-on IT implementation. In IT initiatives involving transformation projects with a strategic component, he is at home just as in end-to-end deployments of new software with innovative UI/UX. Alexander Käther operates confidently in both business and IT, effectively bridging the gap between the two. | AL18: IT Information Technology (Hauke G.) | AM18: AM IT-Architecture Management (Wilfried W.) | AN18: ITM IT-Management (Jörg M.) | AO18: bridgingIT GmbH | AP18: Stuttgart | AQ18: Wilfried Wessel
A19: 10148 | B19: BA4C90 | C19: https://app.matchical.com/Consulting/ConsultantDetail?ConsultantId=4fc60955-ce30-4a69-b133-251d5aba3c20 | D19: Alexander Mai | E19: alexander.mai@bridging-it.de | F19: 45061 | G19: 43525 | H19: 7 | I19: 0 | J19: 1 | K19: 45657 | L19: 45761 | M19: 45869 | N19: FALSE | O19: 33 | P19: 41.46 | Q19: 33.38 | R19: =ROUND(O19-P19,2) | S19: =ROUND(O19-Q19,2) | T19: =IFERROR(P19/O19,"") | U19: =IFERROR(Q19/O19,"") | V19: 50 | W19: 40.5 | X19: 40.5 | Y19: =ROUND(V19-W19,2) | Z19: =ROUND(V19-X19,2) | AA19: =IFERROR(W19/V19,"") | AB19: =IFERROR(X19/V19,"") | AC19: FALSE | AD19: FALSE | AE19: FALSE | AF19: Yes | AG19: 46082 | AI19: TRUE | AJ19: 0.05 | AK19: I have a project, but I would like to switch if a more technical project becomes available. Kubernetes is the main focus. | AL19: IT - Information Technology (Sebastian L.) | AM19: DOE DevOps Enablement (Florian W.) | AN19: C&DO - Cloud & DevOps (Sebastian L.) | AO19: bridgingIT GmbH | AP19: Mannheim | AQ19: Florian Wendel
A20: 7048 | B20: A7B3EC | C20: https://app.matchical.com/Consulting/ConsultantDetail?ConsultantId=360ab819-fb0d-4dcc-99b1-b8168d2b77ff | D20: Alexander Neben | E20: alexander.neben@bridging-it.de | F20: 44805 | G20: 41183 | H20: 6 | I20: 0 | J20: 1 | K20: 44886 | L20: 44817 | M20: 46021 | N20: FALSE | O20: 42 | P20: 79 | Q20: 41.79 | R20: =ROUND(O20-P20,2) | S20: =ROUND(O20-Q20,2) | T20: =IFERROR(P20/O20,"") | U20: =IFERROR(Q20/O20,"") | V20: 119 | W20: 108 | X20: 77 | Y20: =ROUND(V20-W20,2) | Z20: =ROUND(V20-X20,2) | AA20: =IFERROR(W20/V20,"") | AB20: =IFERROR(X20/V20,"") | AC20: FALSE | AD20: FALSE | AE20: FALSE | AF20: Yes | AG20: 46059 | AH20: 46072 | AI20: TRUE | AJ20: 5 | AL20: ORG bIT | AM20: SHH Standort Hamburg (Claudia P.) | AN20: SHH Standort Hamburg (Claudia P) | AO20: bridgingIT GmbH | AP20: Hamburg | AQ20: Claudia Peters
A21: 10434 | B21: 4165F5 | C21: https://app.matchical.com/Consulting/ConsultantDetail?ConsultantId=b1ed7480-989d-45c2-b1b6-73bac484600b | D21: Alexander Schulte | E21: alexander.schulte@bridging-it.de | F21: 46054 | G21: 40391 | H21: 8 | I21: 0 | J21: 0 | L21: 45107 | M21: 45656 | N21: FALSE | O21: 1 | P21: 0 | Q21: 0 | R21: =ROUND(O21-P21,2) | S21: =ROUND(O21-Q21,2) | T21: =IFERROR(P21/O21,"") | U21: =IFERROR(Q21/O21,"") | V21: 186 | W21: 93 | X21: 70 | Y21: =ROUND(V21-W21,2) | Z21: =ROUND(V21-X21,2) | AA21: =IFERROR(W21/V21,"") | AB21: =IFERROR(X21/V21,"") | AC21: FALSE | AD21: FALSE | AE21: FALSE | AF21: Yes | AG21: 46054 | AI21: TRUE | AJ21: 5 | AL21: IT - Information Technology (HH) | AM21: IPM - IT PM (Peter T.) | AN21: MWT HH (Udo P.) | AO21: bridgingIT GmbH | AP21: Hamburg | AQ21: Peter Triftshäuser
A22: 10065 | B22: 986EA5 | C22: https://app.matchical.com/Consulting/ConsultantDetail?ConsultantId=35086c7e-da1f-4f51-8fed-75d05a5930f3 | D22: Alexander Wittmann | E22: alexander.wittmann@bridging-it.de | F22: 44958 | G22: 42795 | H22: 11 | I22: 0 | J22: 3 | K22: 45626 | L22: 45550 | M22: 45746 | N22: FALSE | O22: 37 | P22: 77 | Q22: 35 | R22: =ROUND(O22-P22,2) | S22: =ROUND(O22-Q22,2) | T22: =IFERROR(P22/O22,"") | U22: =IFERROR(Q22/O22,"") | V22: 71 | W22: 87 | X22: 54 | Y22: =ROUND(V22-W22,2) | Z22: =ROUND(V22-X22,2) | AA22: =IFERROR(W22/V22,"") | AB22: =IFERROR(X22/V22,"") | AC22: FALSE | AD22: FALSE | AE22: FALSE | AF22: No | AI22: TRUE | AJ22: 0 | AK22: DevOps, cloud architecture, development experience | AL22: IT - Information Technology (Sebastian L.) | AM22: DOE DevOps Enablement (Florian W.) | AN22: C&DO - Cloud & DevOps (Sebastian L.) | AO22: bridgingIT GmbH | AP22: Mannheim | AQ22: Florian Wendel
A23: 10333 | B23: B90484 | C23: https://app.matchical.com/Consulting/ConsultantDetail?ConsultantId=65e11dc6-ed62-4cbe-8468-42c99a28c7cc | D23: Alexandra Schwarz | E23: alexandra.schwarz@bridging-it.de | F23: 45566 | G23: 43617 | H23: 9 | I23: 0 | J23: 1 | K23: 45596 | L23: 45151 | M23: 45401 | N23: FALSE | O23: 17 | P23: 16 | Q23: 16 | R23: =ROUND(O23-P23,2) | S23: =ROUND(O23-Q23,2) | T23: =IFERROR(P23/O23,"") | U23: =IFERROR(Q23/O23,"") | V23: 64 | W23: 57 | X23: 55.5 | Y23: =ROUND(V23-W23,2) | Z23: =ROUND(V23-X23,2) | AA23: =IFERROR(W23/V23,"") | AB23: =IFERROR(X23/V23,"") | AC23: FALSE | AD23: FALSE | AE23: FALSE | AF23: No | AI23: TRUE | AJ23: 0 | AL23: ORG bIT | AM23: BABC - BA and Business Complexity (Karola B.) | AN23: ABC Analysing Business & Collaboration (Edgar K.) | AO23: bridgingIT GmbH | AP23: Frankfurt | AQ23: Karola Bischof
A24: 1500 | B24: 5DBECD | C24: https://app.matchical.com/Consulting/ConsultantDetail?ConsultantId=50a1aae9-ac3c-44f3-a7b8-ed53e0be1801 | D24: Alexandra Welter | E24: alexandra.welter@bridging-it.de | F24: 44652 | G24: 42917 | H24: 7 | I24: 0 | J24: 0 | L24: 45839 | M24: 45930 | N24: FALSE | O24: 47 | P24: 53.92 | Q24: 42.23 | R24: =ROUND(O24-P24,2) | S24: =ROUND(O24-Q24,2) | T24: =IFERROR(P24/O24,"") | U24: =IFERROR(Q24/O24,"") | V24: 57 | W24: 67.06 | X24: 57 | Y24: =ROUND(V24-W24,2) | Z24: =ROUND(V24-X24,2) | AA24: =IFERROR(W24/V24,"") | AB24: =IFERROR(X24/V24,"") | AC24: FALSE | AD24: FALSE | AE24: FALSE | AF24: Yes | AG24: 46113 | AI24: TRUE | AJ24: 5 | AK24: Alex has extensive experience in agile and traditional project management, rollout and interim management, as well as in organizational and change management — particularly in the retail and life sciences industries. | AL24: T&A - Transformation & Agility (Arne K.) | AM24: P&OS - Processes & Organizational Str. (Raina B.) | AN24: TB - Transforming Business (Arne K.) | AO24: bridgingIT GmbH | AP24: Mannheim | AQ24: Raina Beck
A25: 10269 | B25: 00AD2B | C25: https://app.matchical.com/Consulting/ConsultantDetail?ConsultantId=5631ca75-1d76-4afa-81c7-905e09b62c79 | D25: Alexej Walther | E25: alexej.walther@bridging-it.de | F25: 45413 | G25: 42186 | H25: 18 | I25: 0 | J25: 2 | K25: 45412 | L25: 45445 | M25: 45534 | N25: FALSE | O25: 22 | P25: 40.97 | Q25: 20.98 | R25: =ROUND(O25-P25,2) | S25: =ROUND(O25-Q25,2) | T25: =IFERROR(P25/O25,"") | U25: =IFERROR(Q25/O25,"") | V25: 106 | W25: 259.03 | X25: 80.02 | Y25: =ROUND(V25-W25,2) | Z25: =ROUND(V25-X25,2) | AA25: =IFERROR(W25/V25,"") | AB25: =IFERROR(X25/V25,"") | AC25: FALSE | AD25: FALSE | AE25: FALSE | AF25: No | AI25: TRUE | AJ25: 0 | AL25: IT Information Technology (Hauke G.) | AM25: CT Cloud Technology II (Marc L.) | AN25: TC Technology & Cloud (Martin S.) | AO25: bridgingIT GmbH | AP25: Stuttgart | AQ25: Marc Leunig
A26: 10129 | B26: C58D1E | C26: https://app.matchical.com/Consulting/ConsultantDetail?ConsultantId=2aa0b085-d204-4627-8c3e-2e1a8973b6f0 | D26: Ali Karaarslan | E26: ali.karaarslan@bridging-it.de | F26: 45047 | G26: 43922 | H26: 5 | I26: 0 | J26: 0 | L26: 45396 | M26: 45656 | N26: FALSE | O26: 34 | P26: 31.97 | Q26: 22.98 | R26: =ROUND(O26-P26,2) | S26: =ROUND(O26-Q26,2) | T26: =IFERROR(P26/O26,"") | U26: =IFERROR(Q26/O26,"") | V26: 37 | W26: 30 | X26: 29.99 | Y26: =ROUND(V26-W26,2) | Z26: =ROUND(V26-X26,2) | AA26: =IFERROR(W26/V26,"") | AB26: =IFERROR(X26/V26,"") | AC26: FALSE | AD26: FALSE | AE26: FALSE | AF26: No | AI26: TRUE | AJ26: 0 | AL26: ORG bIT | AM26: SE Software Engineering Frankfurt (Steffen F.) | AN26: ES Enterprise Solutions (Dominik H.) | AO26: bridgingIT GmbH | AP26: Frankfurt | AQ26: Steffen Flick
A27: 9570 | B27: 5A6FD1 | C27: https://app.matchical.com/Consulting/ConsultantDetail?ConsultantId=3d36865e-1d68-4b82-8f9f-6190cdda7e3b | D27: Alwina Bonk | E27: alwina.bonk@leistungen.de | F27: 43374 | H27: 0 | I27: 0 | J27: 0 | N27: TRUE | O27: 89 | P27: 0 | Q27: 0 | R27: =ROUND(O27-P27,2) | S27: =ROUND(O27-Q27,2) | T27: =IFERROR(P27/O27,"") | U27: =IFERROR(Q27/O27,"") | V27: 1425 | W27: 0 | X27: 0 | Y27: =ROUND(V27-W27,2) | Z27: =ROUND(V27-X27,2) | AA27: =IFERROR(W27/V27,"") | AB27: =IFERROR(X27/V27,"") | AC27: FALSE | AD27: FALSE | AE27: FALSE | AF27: No | AI27: TRUE | AJ27: 0 | AL27: Geschäftsleitung und Support | AM27: Support Externe Partner | AN27: Frank Wallner | AO27: bridgingIT GmbH | AP27: Mannheim | AQ27: Nina Beckenbach
A28: 10340 | B28: 9617C1 | C28: https://app.matchical.com/Consulting/ConsultantDetail?ConsultantId=a8566670-a574-40b4-894e-61297b3d2201 | D28: Amadou Wolfgang Cisse | E28: amadou.cisse@bridging-it.de | F28: 45597 | H28: 10 | I28: 0 | J28: 1 | K28: 44804 | L28: 45719 | M28: 45807 | N28: FALSE | O28: 16 | P28: 22.46 | Q28: 15.09 | R28: =ROUND(O28-P28,2) | S28: =ROUND(O28-Q28,2) | T28: =IFERROR(P28/O28,"") | U28: =IFERROR(Q28/O28,"") | V28: 1498 | W28: 88.54 | X28: 46.91 | Y28: =ROUND(V28-W28,2) | Z28: =ROUND(V28-X28,2) | AA28: =IFERROR(W28/V28,"") | AB28: =IFERROR(X28/V28,"") | AC28: FALSE | AD28: FALSE | AE28: FALSE | AF28: Yes | AG28: 46143 | AI28: TRUE | AJ28: 5 | AL28: ORG bIT Bayern | AM28: DSA Data Solutions & AI (Philip R.) | AN28: BPD Business Processes & Data Engineering(Arne K.) | AO28: bridgingIT GmbH | AP28: München | AQ28: Philip Rausch
A29: 10369 | B29: 26A2E7 | C29: https://app.matchical.com/Consulting/ConsultantDetail?ConsultantId=3078fbb8-d547-457a-adba-64739b9b6e67 | D29: Amin Ataei | E29: amin.ataei@bridging-it.de | F29: 45839 | G29: 44197 | H29: 5 | I29: 0 | J29: 0 | L29: 44865 | M29: 45715 | N29: FALSE | O29: 8 | P29: 10.68 | Q29: 7.82 | R29: =ROUND(O29-P29,2) | S29: =ROUND(O29-Q29,2) | T29: =IFERROR(P29/O29,"") | U29: =IFERROR(Q29/O29,"") | V29: 54 | W29: 48 | X29: 45.49 | Y29: =ROUND(V29-W29,2) | Z29: =ROUND(V29-X29,2) | AA29: =IFERROR(W29/V29,"") | AB29: =IFERROR(X29/V29,"") | AC29: FALSE | AD29: FALSE | AE29: FALSE | AF29: Yes | AG29: 46113 | AI29: FALSE | AJ29: 5 | AK29: Cloud & DevOps Engineer with a focus on Microsoft Azure, automation, and Infrastructure as Code (IaC). Strong expertise in the development and implementation of cloud architectures, CI/CD pipelines, and IT security. Extensive experience with Terraform, PowerShell, and Docker. Passionate about cloud automation and DevOps culture. | AL29: IT - Information Technology (Sebastian L.) | AM29: DOE DevOps Enablement (Florian W.) | AN29: C&DO - Cloud & DevOps (Sebastian L.) | AO29: bridgingIT GmbH | AP29: Mannheim | AQ29: Florian Wendel
A30: 7018 | B30: F6B176 | C30: https://app.matchical.com/Consulting/ConsultantDetail?ConsultantId=e2dd0b01-309a-402d-abe0-2e1b80205a9f | D30: Anastasia Rettberg-Kluter | E30: anastasia.rettberg-kluter@fastahead.com | F30: 43160 | G30: 41214 | H30: 16 | I30: 0 | J30: 1 | K30: 44928 | L30: 44719 | M30: 44926 | N30: FALSE | O30: 96 | P30: 116 | Q30: 92 | R30: =ROUND(O30-P30,2) | S30: =ROUND(O30-Q30,2) | T30: =IFERROR(P30/O30,"") | U30: =IFERROR(Q30/O30,"") | V30: 64 | W30: 46 | X30: 31 | Y30: =ROUND(V30-W30,2) | Z30: =ROUND(V30-X30,2) | AA30: =IFERROR(W30/V30,"") | AB30: =IFERROR(X30/V30,"") | AC30: FALSE | AD30: FALSE | AE30: FALSE | AF30: Yes | AG30: 46204 | AI30: TRUE | AJ30: 5 | AL30: ORG fastahead GmbH & Co. KG | AM30: User Experience Design | AN30: fah Tim Thierfelder | AO30: fastahead GmbH & Co. KG | AP30: Berlin | AQ30: Tim Thierfelder
A31: 10007 | B31: 67B144 | C31: https://app.matchical.com/Consulting/ConsultantDetail?ConsultantId=00713c49-1d9f-4cca-8954-7f1ffce1269b | D31: Anatoli Schäfer | E31: anatoli.schaefer@bridging-it.de | F31: 44866 | G31: 44562 | H31: 9 | I31: 0 | J31: 0 | L31: 45658 | M31: 46022 | N31: FALSE | O31: 40 | P31: 38.97 | Q31: 38.97 | R31: =ROUND(O31-P31,2) | S31: =ROUND(O31-Q31,2) | T31: =IFERROR(P31/O31,"") | U31: =IFERROR(Q31/O31,"") | V31: 10 | W31: 8 | X31: 8 | Y31: =ROUND(V31-W31,2) | Z31: =ROUND(V31-X31,2) | AA31: =IFERROR(W31/V31,"") | AB31: =IFERROR(X31/V31,"") | AC31: FALSE | AD31: FALSE | AE31: FALSE | AF31: No | AI31: FALSE | AJ31: 0 | AL31: A&SE Analytics & Software Engineering (Philip R.) | AM31: FV Fullstack Visionaries (Matthias H.) | AN31: FUN Fullstack Ninjas (Stefan Z.) | AO31: bridgingIT GmbH | AP31: Mannheim | AQ31: Matthias Hetz
A32: 10264 | B32: E9AC01 | C32: https://app.matchical.com/Consulting/ConsultantDetail?ConsultantId=1b6f2d18-bb04-4f51-9faf-6516176ba681 | D32: Andre Hein | E32: andre.hein@bridging-it.de | F32: 45383 | G32: 40330 | H32: 12 | I32: 0 | J32: 2 | K32: 45596 | L32: 45397 | M32: 45657 | N32: FALSE | O32: 23 | P32: 39 | Q32: 21 | R32: =ROUND(O32-P32,2) | S32: =ROUND(O32-Q32,2) | T32: =IFERROR(P32/O32,"") | U32: =IFERROR(Q32/O32,"") | V32: 166 | W32: 150 | X32: 74 | Y32: =ROUND(V32-W32,2) | Z32: =ROUND(V32-X32,2) | AA32: =IFERROR(W32/V32,"") | AB32: =IFERROR(X32/V32,"") | AC32: FALSE | AD32: FALSE | AE32: FALSE | AF32: No | AI32: TRUE | AJ32: 0 | AL32: T&A - Transformation & Agility (Arne K.) | AM32: CTM – Change & Transformationmgmt. HH (Katja R.) | AN32: A&PM Agility & Project Management (Jan H.) | AO32: bridgingIT GmbH | AP32: Hamburg | AQ32: Katja Runge
A33: 8687 | B33: 6161A5 | C33: https://app.matchical.com/Consulting/ConsultantDetail?ConsultantId=9c4bab4b-c38b-4386-a474-b976cad6f763 | D33: André Krippendorf | E33: andre.krippendorf@crafting-it.de | F33: 44348 | G33: 41456 | H33: 15 | I33: 0 | J33: 2 | K33: 44561 | L33: 45364 | M33: 45657 | N33: FALSE | O33: 57 | P33: 210.79 | Q33: 56.8 | R33: =ROUND(O33-P33,2) | S33: =ROUND(O33-Q33,2) | T33: =IFERROR(P33/O33,"") | U33: =IFERROR(Q33/O33,"") | V33: 95 | W33: 0 | X33: 0 | Y33: =ROUND(V33-W33,2) | Z33: =ROUND(V33-X33,2) | AA33: =IFERROR(W33/V33,"") | AB33: =IFERROR(X33/V33,"") | AC33: FALSE | AD33: FALSE | AE33: FALSE | AF33: Yes | AG33: 45931 | AI33: TRUE | AJ33: 3 | AK33: Occasional on-site client meetings can indeed be represented. | AL33: ORG cIT | AM33: cIT Development | AN33: cIT Service Delivery Magdeburg (Steffen A.) | AO33: craftingIT GmbH | AP33: Magdeburg | AQ33: Jennifer Saalfeld
A34: 8722 | B34: 3F7D01 | C34: https://app.matchical.com/Consulting/ConsultantDetail?ConsultantId=89e26302-5625-42b2-b010-1cb4a8bc8554 | D34: Andre Lexow | E34: andre.lexow@crafting-it.de | F34: 44545 | G34: 44545 | H34: 20 | I34: 0 | J34: 1 | K34: 46022 | L34: 45658 | M34: 46022 | N34: FALSE | O34: 50 | P34: 195.14 | Q34: 50.33 | R34: =ROUND(O34-P34,2) | S34: =ROUND(O34-Q34,2) | T34: =IFERROR(P34/O34,"") | U34: =IFERROR(Q34/O34,"") | V34: 0 | W34: 0 | X34: 0 | Y34: =ROUND(V34-W34,2) | Z34: =ROUND(V34-X34,2) | AA34: =IFERROR(W34/V34,"") | AB34: =IFERROR(X34/V34,"") | AC34: FALSE | AD34: FALSE | AE34: FALSE | AF34: Yes | AG34: 45809 | AI34: TRUE | AJ34: 3 | AL34: ORG cIT | AM34: cIT AMS / GIS Services (Michael B.) | AN34: cIT Service Delivery Magdeburg (Steffen A.) | AO34: craftingIT GmbH | AP34: Magdeburg | AQ34: Michael Buchter
A35: 1327 | B35: E894F1 | C35: https://app.matchical.com/Consulting/ConsultantDetail?ConsultantId=97ba9131-62f0-433e-b541-fbbb5b2d5e22 | D35: Andreas Bürkle | E35: andreas.buerkle@bridging-it.de | F35: 42384 | G35: 39448 | H35: 17 | I35: 0 | J35: 2 | K35: 44423 | L35: 42442 | M35: 45827 | N35: FALSE | O35: 121 | P35: 386.9 | Q35: 120.97 | R35: =ROUND(O35-P35,2) | S35: =ROUND(O35-Q35,2) | T35: =IFERROR(P35/O35,"") | U35: =IFERROR(Q35/O35,"") | V35: 96 | W35: 71 | X35: 71 | Y35: =ROUND(V35-W35,2) | Z35: =ROUND(V35-X35,2) | AA35: =IFERROR(W35/V35,"") | AB35: =IFERROR(X35/V35,"") | AC35: FALSE | AD35: FALSE | AE35: FALSE | AF35: Yes | AG35: 46023 | AI35: TRUE | AJ35: 5 | AK35: Target role: RTE, Scrum Master, Agile Coach Industry experience: Automotive, Retail, Pharmaceutical, Energy Willingness to travel: Occasional travel to Frankfurt, Stuttgart, and Cologne is acceptable. Up to three hotel overnight stays per month are acceptable. | AL35: T&A - Transformation & Agility (Arne K.) | AM35: HPMI - Hybrid Project Mgmt & Innovat. (Sascha W.) | AN35: A&PM Agility & Project Management (Jan H.) | AO35: bridgingIT GmbH | AP35: Mannheim | AQ35: Sascha Wacker
A36: 10357 | B36: 8574CB | C36: https://app.matchical.com/Consulting/ConsultantDetail?ConsultantId=9373d136-b4bf-4a1c-b467-e0440d963037 | D36: Andreas Diel | E36: andreas.diel@fastahead.com | F36: 45748 | G36: 35765 | H36: 20 | I36: 0 | J36: 0 | L36: 45838 | M36: 45960 | N36: FALSE | O36: 11 | P36: 4.76 | Q36: 4.76 | R36: =ROUND(O36-P36,2) | S36: =ROUND(O36-Q36,2) | T36: =IFERROR(P36/O36,"") | U36: =IFERROR(Q36/O36,"") | V36: 328 | W36: 278 | X36: 127 | Y36: =ROUND(V36-W36,2) | Z36: =ROUND(V36-X36,2) | AA36: =IFERROR(W36/V36,"") | AB36: =IFERROR(X36/V36,"") | AC36: FALSE | AD36: FALSE | AE36: FALSE | AF36: No | AI36: TRUE | AJ36: 0 | AK36: Key skills: Banking, Finance, Strategy consulting, KPI systems, Spanish | AL36: ORG fastahead GmbH & Co. KG | AM36: Banking (R. Weygand) | AN36: fah Ralf Weygand | AO36: fastahead GmbH & Co. KG | AP36: Köln | AQ36: Ralf Weygand
A37: 1040 | B37: DA65EB | C37: https://app.matchical.com/Consulting/ConsultantDetail?ConsultantId=f9614ca2-7a00-4b51-9ecb-13f7c5e79b23 | D37: Andreas Dietz | E37: andreas.dietz@bridging-it.de | F37: 39569 | G37: 36526 | H37: 30 | I37: 0 | J37: 2 | K37: 41274 | L37: 41275 | M37: 45715 | N37: FALSE | O37: 214 | P37: 924.94 | Q37: 213.82 | R37: =ROUND(O37-P37,2) | S37: =ROUND(O37-Q37,2) | T37: =IFERROR(P37/O37,"") | U37: =IFERROR(Q37/O37,"") | V37: 100 | W37: 96.06 | X37: 91.88 | Y37: =ROUND(V37-W37,2) | Z37: =ROUND(V37-X37,2) | AA37: =IFERROR(W37/V37,"") | AB37: =IFERROR(X37/V37,"") | AC37: FALSE | AD37: FALSE | AE37: FALSE | AF37: Yes | AG37: 46037 | AH37: 46080 | AI37: FALSE | AJ37: 2.5 | AK37: Andreas works at the start of the year at 50% (4 hours per day) | AL37: ORG bIT | AM37: PITS Professional IT-Services (Martin R.) | AN37: MIT Management of IT (Torsten R.) | AO37: bridgingIT GmbH | AP37: Frankfurt | AQ37: Martin Redemsky
A38: 2284 | B38: 47D30E | C38: https://app.matchical.com/Consulting/ConsultantDetail?ConsultantId=5a972972-e205-4df7-b8d4-328765f2877d | D38: Andreas Glasa | E38: andreas.glasa@bridging-it.de | F38: 44470 | G38: 39510 | H38: 6 | I38: 0 | J38: 2 | K38: 44695 | L38: 45504 | M38: 45776 | N38: FALSE | O38: 53 | P38: 115 | Q38: 52.8 | R38: =ROUND(O38-P38,2) | S38: =ROUND(O38-Q38,2) | T38: =IFERROR(P38/O38,"") | U38: =IFERROR(Q38/O38,"") | V38: 163 | W38: 34 | X38: 34 | Y38: =ROUND(V38-W38,2) | Z38: =ROUND(V38-X38,2) | AA38: =IFERROR(W38/V38,"") | AB38: =IFERROR(X38/V38,"") | AC38: FALSE | AD38: FALSE | AE38: FALSE | AF38: No | AI38: TRUE | AJ38: 0 | AK38: Andreas is a highly experienced Agile Coach/RTE and SAFe trainer. | AL38: DO Digital Organizations (Michael H.) | AM38: AO Agile Organizations (Andreas G.) | AN38: BT Business Transformation (Julian D.) | AO38: bridgingIT GmbH | AP38: Stuttgart | AQ38: Julian Dahlbender
A39: 2236 | B39: D992B7 | C39: https://app.matchical.com/Consulting/ConsultantDetail?ConsultantId=e4f77298-25ef-4c96-9dc5-f5a8f77253f7 | D39: Andreas Hellner | E39: andreas.hellner@bridging-it.de | F39: 43466 | G39: 40756 | H39: 7 | I39: 0 | J39: 1 | K39: 44885 | L39: 43830 | M39: 44546 | N39: FALSE | O39: 86 | P39: 74 | Q39: 70 | R39: =ROUND(O39-P39,2) | S39: =ROUND(O39-Q39,2) | T39: =IFERROR(P39/O39,"") | U39: =IFERROR(Q39/O39,"") | V39: 89 | W39: 89.46 | X39: 89.03 | Y39: =ROUND(V39-W39,2) | Z39: =ROUND(V39-X39,2) | AA39: =IFERROR(W39/V39,"") | AB39: =IFERROR(X39/V39,"") | AC39: FALSE | AD39: FALSE | AE39: FALSE | AF39: No | AI39: FALSE | AJ39: 5 | AK39: Key skills: * .NET software development (Backend) * Azure * Software architecture | AL39: ES Enterprise Solutions (Gina H.) | AM39: IEM .Net I (Christoph M.) | AN39: IEJ Individualentwicklung JAVA (Dominik S.) | AO39: bridgingIT GmbH | AP39: Stuttgart | AQ39: Christoph Müller
A40: 10164 | B40: 38CDEF | C40: https://app.matchical.com/Consulting/ConsultantDetail?ConsultantId=e27d9444-1faf-468a-bd3e-be13f2d08b2a | D40: Andreas Hofmann | E40: andreas.hofmann@fastahead.com | F40: 45170 | G40: 36800 | H40: 10 | I40: 0 | J40: 0 | L40: 45748 | M40: 46022 | N40: FALSE | O40: 30 | P40: 18.02 | Q40: 18.02 | R40: =ROUND(O40-P40,2) | S40: =ROUND(O40-Q40,2) | T40: =IFERROR(P40/O40,"") | U40: =IFERROR(Q40/O40,"") | V40: 275 | W40: 136.98 | X40: 95.98 | Y40: =ROUND(V40-W40,2) | Z40: =ROUND(V40-X40,2) | AA40: =IFERROR(W40/V40,"") | AB40: =IFERROR(X40/V40,"") | AC40: FALSE | AD40: FALSE | AE40: FALSE | AF40: Yes | AG40: 46023 | AI40: TRUE | AJ40: 5 | AK40: Financial Services, Banking and Credit Industry, Technology, Structured Finance, Distributed Ledger Technologies, Regulation, Project Management, Interim Management | AL40: ORG fastahead GmbH & Co. KG | AM40: Banking (R. Weygand) | AN40: fah Ralf Weygand | AO40: fastahead GmbH & Co. KG | AP40: München | AQ40: Ralf Weygand
...

Sheet Lists
A1: Metric_type | B1: Department | C1: Team | D1: Unit | E1: Legal_entity | F1: Location | G1: Lead | H1: Is_available | I1: Segment_dimension
A2: Weighted | B2: All | C2: All | D2: All | E2: All | F2: All | G2: All | H2: All | I2: Department
A3: Absolute | B3: A&SE Analytics & Software Engineering (Philip R.) | C3: A&PM Agility & Project Management (Lutz K.) | D3: A&DDS - Analytics & Data-driven Solutions (M. Hof) | E3: bridgingIT GmbH | F3: Berlin | G3: Aleksandar Blagojevic | H3: - | I3: Team
B4: BusDev | C4: AAC - Advanced Automation Cologne (Claudia P.) | D4: A&PM Agility & Project Management (Jan H.) | E4: craftingIT GmbH | F4: Frankfurt | G4: Alexander Jende | H4: No | I4: Unit
B5: DO Digital Organizations (Michael H.) | C5: AI Artificial Intelligence (Philip R.) | D5: A&SE Analytics & Software Engineering (Philip R.) | E5: fastahead GmbH & Co. KG | F5: Hamburg | G5: Anastasia Rettberg-Kluter | H5: Yes | I5: Legal entity
B6: ES Enterprise Solutions (Gina H.) | C6: AM IT-Architecture Management (Wilfried W.) | D6: ABC Analysing Business & Collab. BLN (Edgar K.) | F6: Karlsruhe | G6: Andreas Glasa | I6: Location
B7: ES Enterprise Solutions BLN (Gina H.) | C7: AMC - Agility Masters Cologne (Severin E.) | D7: ABC Analysing Business & Collaboration (Edgar K.) | F7: Köln | G7: Andreas Kernbach | I7: Lead
B8: Geschäftsleitung und Support | C8: AO Agile Organization (Katharina G.) | D8: BAA HH (Torben H.) | F8: Magdeburg | G8: Andreas Morgenstern
B9: IT - Information Technology (HH) | C9: AO Agile Organizations (Andreas G.) | D9: BAT Business Agility & Transformation (Marc S.) | F9: Mannheim | G9: Anna Schnorrenberger
B10: IT - Information Technology (Sebastian L.) | C10: AT Agile Transformation (Anna S.) | D10: BE Business Engineering (Heidi Foldenauer) | F10: München | G10: Arne Kunstmann
B11: IT Information Technology (Hauke G.) | C11: Agile Innovation - AIN (Simon S.) | D11: BPD Business Processes & Data Engineering(Arne K.) | F11: Nürnberg | G11: Barbara Vettel
B12: ORG bIT | C12: BA - Business Applications (Hamed S.) | D12: BT Business Transformation (Julian D.) | F12: Stuttgart | G12: Bastian Trauth
B13: ORG bIT Bayern | C13: BAA Business Analysis & Architecture (Viktor P.) | D13: BTC - Business Transformation Cologne (Anna S.) | G13: Bernd Opitz
B14: ORG cIT | C14: BAAM - Management (Torben H.) | D14: BW Expertenteams | G14: Boris Bergner
B15: ORG cIT 2 | C15: BABA - BA and Business Architectures (Carsten S.) | D15: C&DO - Cloud & DevOps (Sebastian L.) | G15: Carmen Deubelbeiss
B16: ORG fastahead GmbH & Co. KG | C16: BABC - BA and Business Complexity (Karola B.) | D16: CC Life Science Solutions (Sabine S.) | G16: Carsten Schindler
B17: POR BL | C17: BABC - BA and Business Complexity BLN (Karola B.) | D17: CEO | G17: Carsten Triebel
B18: Sales BL | C18: BAPO - BA and Product Ownership (Edgar K.) | D18: COO | G18: Christian Gitte
B19: T&A - Transformation & Agility (Arne K.) | C19: BPE Business Process Excellence (Heidi F.) | D19: Capability Management (Tim T.) | G19: Christian Kobl
B20: TPD cIT - BL Third Party Delivery (Christian K.) | C20: BT Business Transform. II (Patrick D.) | D20: DO Line Management (Michael H.) | G20: Christian Will
C21: BT Business Transform. III (Valerie L.) | D21: DP Digital Processes (Hermann L.) | G21: Christian Wolf
C22: BT Unit Management (Julian D.) | D22: DPC - Datalytics & Process Cologne (Claudia P.) | G22: Christoph Müller
C23: Banking (R. Weygand) | D23: ES Enterprise Solutions (Dominik H.) | G23: Christoph Wudtke
C24: Business Agility & Transformation - Management | D24: ES Line Management (Gina H.) | G24: Christopher Schweinsteiger
C25: Business Transformation (BT) (Stefan S.) | D25: FUN Fullstack Ninjas (Stefan Z.) | G25: Claudia Peters
C26: Business-driven Architectures (Dr. C. Gitte) | D26: Frank Wallner | G26: Clemens Lindner
C27: CC Content & Collaboration (Frank G.) | D27: GRC IT-GRC (Erhan N.) | G27: Dana Thüring
C28: CDC - Cloud & DevOps Cologne (Henning F.) | D28: IEJ Individualentwicklung JAVA (Dominik S.) | G28: Daniel Rheinwalt
C29: CDI Cloud DevOps & IT-Architecture (Tim J.) | D29: IT Information Technology (Sebastian L.) | G29: David Schleweis
C30: CG - Cloud Governance (Leyla V.) | D30: IT Line-Management (Hauke G.) | G30: David Turan
C31: CIS Compliance & Information Security (David T.) | D31: ITBLM - Management (Markus S.) | G31: Dean Herzog-Meijer
C32: CRM I - Platform Solutions & CRM (Fortunato D. D.) | D32: ITC HH (Nicole F.) | G32: Diana Gülker
... C67: IEM .Net II (Aleksandar B.) | D67: fah Tim Thierfelder | G67: Marc Schmitt
C68: IPM - IT PM (Peter T.) | G68: Marcel Kelle
C69: ISM Information Security Management (Carsten T.) | G69: Marita Dorscheid
C70: IT Line Management (Hauke G.) | G70: Markus Stefan
C71: IT-Strategy & EAM (D. Rheinwalt) | G71: Martin Klingenberg
C72: IT-Transition (D. Rheinwalt) | G72: Martin Kuck
C73: ITBLM - Management (Markus S.) | G73: Martin Redemsky
C74: ITCM - Management (Nicole F.) | G74: Martin Spörl
...

Sheet Model
A1: Include | B1: Selected_ratio_since | C1: Selected_ratio_before | D1: Ongoing_age_months | E1: Availability_inconsistency | F1: Anomaly_flag | G1: Segment_value | H1: Low_coverage_flag | I1: Anomaly_score | J1: Candidate_segment | K1: Candidate_total | L1: Candidate_low | M1: Candidate_low_rate | N1: Candidate_rank_key | O1: Top_segment | P1: Top_low_rate | Q1: Top_count | R1: Rank_key | S1: Selected_since_included | T1: Selected_before_included | U1: Weighted_since_included | V1: Weighted_before_included
A2: =--(AND(OR(Dashboard!$B$4="All",Raw_data!$AL2=Dashboard!$B$4),OR(Dashboard!$B$5="All",Raw_data!$AM2=Dashboard!$B$5),OR(Dashboard!$B$6="All",Raw_data!$AN2=Dashboard!$B$6),OR(Dashboard!$B$7="All",Raw_data!$AO2=Dashboard!$B$7),OR(Dashboard!$B$8="All",Raw_data!$AP2=Dashboard!$B$8),OR(Dashboard!$B$9="All",Raw_data!$AQ2=Dashboard!$B$9),OR(Dashboard!$B$10="All",Raw_data!$AF2=Dashboard!$B$10),OR(Raw_data!$F2="",Raw_data!$F2<=TODAY()))) | B2: =IFERROR(IF(Dashboard!$B$3="Weighted",Raw_data!$U2,Raw_data!$T2),"") | C2: =IFERROR(IF(Dashboard!$B$3="Weighted",Raw_data!$AB2,Raw_data!$AA2),"") | D2: =IF(OR(Raw_data!$J2="",Raw_data!$J2<=0,Raw_data!$K2=""),"",IF(Raw_data!$K2>TODAY(),0,DATEDIF(Raw_data!$K2,TODAY(),"M"))) | E2: =--(AND(Raw_data!$AF2="No",OR(Raw_data!$AG2<>"",Raw_data!$AJ2>0,Raw_data!$AK2<>""))) | F2: =--(OR(AND(ISNUMBER(B2),B2<0.5,OR(D2>=24,Raw_data!$I2>0)),Raw_data!$AE2=TRUE)) | G2: =IF(Dashboard!$B$11="Department",Raw_data!$AL2,IF(Dashboard!$B$11="Team",Raw_data!$AM2,IF(Dashboard!$B$11="Unit",Raw_data!$AN2,IF(Dashboard!$B$11="Legal entity",Raw_data!$AO2,IF(Dashboard!$B$11="Location",Raw_data!$AP2,Raw_data!$AQ2))))) | H2: =--(AND(ISNUMBER(B2),B2<0.5)) | I2: =IFERROR(MAX(0,(0.5-B2)*100),0)+IF(D2>=24,20,0)+IF(Raw_data!$I2>0,20,0)+IF(Raw_data!$AE2=TRUE,10,0) | J2: =IFERROR(CHOOSE(MATCH(Dashboard!$B$11,{"Department","Team","Unit","Legal entity","Location","Lead"},0),INDEX(Lists!$B$3:$B$20,ROW()-1),INDEX(Lists!$C$3:$C$146,ROW()-1),INDEX(Lists!$D$3:$D$67,ROW()-1),INDEX(Lists!$E$3:$E$5,ROW()-1),INDEX(Lists!$F$3:$F$12,ROW()-1),INDEX(Lists!$G$3:$G$126,ROW()-1)),"") | K2: =IF(J2="","",SUMPRODUCT(($A$2:$A$636=1)*($G$2:$G$636=J2))) | L2: =IF(J2="","",SUMPRODUCT(($A$2:$A$636=1)*($G$2:$G$636=J2)*(ISNUMBER($B$2:$B$636))*($B$2:$B$636<0.5))) | M2: =IFERROR(L2/K2,"") | N2: =IF(K2="","",M2+K2/100000+ROW()/100000000) | O2: =IFERROR(INDEX($J$2:$J$1001,MATCH(LARGE($N$2:$N$1001,1),$N$2:$N$1001,0)),"") | P2: =IFERROR(INDEX($M$2:$M$1001,MATCH(LARGE($N$2:$N$1001,1),$N$2:$N$1001,0)),"") | Q2: =IFERROR(INDEX($K$2:$K$1001,MATCH(LARGE($N$2:$N$1001,1),$N$2:$N$1001,0)),"") | R2: =IF(A2=1,IFERROR(I2,0)+ROW()/100000000,-1E+99) | S2: =IF(A2=1,IFERROR(Raw_data!$T2,""),"") | T2: =IF(A2=1,IFERROR(Raw_data!$AA2,""),"") | U2: =IF(A2=1,IFERROR(Raw_data!$U2,""),"") | V2: =IF(A2=1,IFERROR(Raw_data!$AB2,""),"")
A3: =--(AND(OR(Dashboard!$B$4="All",Raw_data!$AL3=Dashboard!$B$4),OR(Dashboard!$B$5="All",Raw_data!$AM3=Dashboard!$B$5),OR(Dashboard!$B$6="All",Raw_data!$AN3=Dashboard!$B$6),OR(Dashboard!$B$7="All",Raw_data!$AO3=Dashboard!$B$7),OR(Dashboard!$B$8="All",Raw_data!$AP3=Dashboard!$B$8),OR(Dashboard!$B$9="All",Raw_data!$AQ3=Dashboard!$B$9),OR(Dashboard!$B$10="All",Raw_data!$AF3=Dashboard!$B$10),OR(Raw_data!$F3="",Raw_data!$F3<=TODAY()))) | B3: =IFERROR(IF(Dashboard!$B$3="Weighted",Raw_data!$U3,Raw_data!$T3),"") | C3: =IFERROR(IF(Dashboard!$B$3="Weighted",Raw_data!$AB3,Raw_data!$AA3),"") | D3: =IF(OR(Raw_data!$J3="",Raw_data!$J3<=0,Raw_data!$K3=""),"",IF(Raw_data!$K3>TODAY(),0,DATEDIF(Raw_data!$K3,TODAY(),"M"))) | E3: =--(AND(Raw_data!$AF3="No",OR(Raw_data!$AG3<>"",Raw_data!$AJ3>0,Raw_data!$AK3<>""))) | F3: =--(OR(AND(ISNUMBER(B3),B3<0.5,OR(D3>=24,Raw_data!$I3>0)),Raw_data!$AE3=TRUE)) | G3: =IF(Dashboard!$B$11="Department",Raw_data!$AL3,IF(Dashboard!$B$11="Team",Raw_data!$AM3,IF(Dashboard!$B$11="Unit",Raw_data!$AN3,IF(Dashboard!$B$11="Legal entity",Raw_data!$AO3,IF(Dashboard!$B$11="Location",Raw_data!$AP3,Raw_data!$AQ3))))) | H3: =--(AND(ISNUMBER(B3),B3<0.5)) | I3: =IFERROR(MAX(0,(0.5-B3)*100),0)+IF(D3>=24,20,0)+IF(Raw_data!$I3>0,20,0)+IF(Raw_data!$AE3=TRUE,10,0) | J3: =IFERROR(CHOOSE(MATCH(Dashboard!$B$11,{"Department","Team","Unit","Legal entity","Location","Lead"},0),INDEX(Lists!$B$3:$B$20,ROW()-1),INDEX(Lists!$C$3:$C$146,ROW()-1),INDEX(Lists!$D$3:$D$67,ROW()-1),INDEX(Lists!$E$3:$E$5,ROW()-1),INDEX(Lists!$F$3:$F$12,ROW()-1),INDEX(Lists!$G$3:$G$126,ROW()-1)),"") | K3: =IF(J3="","",SUMPRODUCT(($A$2:$A$636=1)*($G$2:$G$636=J3))) | L3: =IF(J3="","",SUMPRODUCT(($A$2:$A$636=1)*($G$2:$G$636=J3)*(ISNUMBER($B$2:$B$636))*($B$2:$B$636<0.5))) | M3: =IFERROR(L3/K3,"") | N3: =IF(K3="","",M3+K3/100000+ROW()/100000000) | O3: =IFERROR(INDEX($J$2:$J$1001,MATCH(LARGE($N$2:$N$1001,2),$N$2:$N$1001,0)),"") | P3: =IFERROR(INDEX($M$2:$M$1001,MATCH(LARGE($N$2:$N$1001,2),$N$2:$N$1001,0)),"") | Q3: =IFERROR(INDEX($K$2:$K$1001,MATCH(LARGE($N$2:$N$1001,2),$N$2:$N$1001,0)),"") | R3: =IF(A3=1,IFERROR(I3,0)+ROW()/100000000,-1E+99) | S3: =IF(A3=1,IFERROR(Raw_data!$T3,""),"") | T3: =IF(A3=1,IFERROR(Raw_data!$AA3,""),"") | U3: =IF(A3=1,IFERROR(Raw_data!$U3,""),"") | V3: =IF(A3=1,IFERROR(Raw_data!$AB3,""),"")
A4: =--(AND(OR(Dashboard!$B$4="All",Raw_data!$AL4=Dashboard!$B$4),OR(Dashboard!$B$5="All",Raw_data!$AM4=Dashboard!$B$5),OR(Dashboard!$B$6="All",Raw_data!$AN4=Dashboard!$B$6),OR(Dashboard!$B$7="All",Raw_data!$AO4=Dashboard!$B$7),OR(Dashboard!$B$8="All",Raw_data!$AP4=Dashboard!$B$8),OR(Dashboard!$B$9="All",Raw_data!$AQ4=Dashboard!$B$9),OR(Dashboard!$B$10="All",Raw_data!$AF4=Dashboard!$B$10),OR(Raw_data!$F4="",Raw_data!$F4<=TODAY()))) | B4: =IFERROR(IF(Dashboard!$B$3="Weighted",Raw_data!$U4,Raw_data!$T4),"") | C4: =IFERROR(IF(Dashboard!$B$3="Weighted",Raw_data!$AB4,Raw_data!$AA4),"") | D4: =IF(OR(Raw_data!$J4="",Raw_data!$J4<=0,Raw_data!$K4=""),"",IF(Raw_data!$K4>TODAY(),0,DATEDIF(Raw_data!$K4,TODAY(),"M"))) | E4: =--(AND(Raw_data!$AF4="No",OR(Raw_data!$AG4<>"",Raw_data!$AJ4>0,Raw_data!$AK4<>""))) | F4: =--(OR(AND(ISNUMBER(B4),B4<0.5,OR(D4>=24,Raw_data!$I4>0)),Raw_data!$AE4=TRUE)) | G4: =IF(Dashboard!$B$11="Department",Raw_data!$AL4,IF(Dashboard!$B$11="Team",Raw_data!$AM4,IF(Dashboard!$B$11="Unit",Raw_data!$AN4,IF(Dashboard!$B$11="Legal entity",Raw_data!$AO4,IF(Dashboard!$B$11="Location",Raw_data!$AP4,Raw_data!$AQ4))))) | H4: =--(AND(ISNUMBER(B4),B4<0.5)) | I4: =IFERROR(MAX(0,(0.5-B4)*100),0)+IF(D4>=24,20,0)+IF(Raw_data!$I4>0,20,0)+IF(Raw_data!$AE4=TRUE,10,0) | J4: =IFERROR(CHOOSE(MATCH(Dashboard!$B$11,{"Department","Team","Unit","Legal entity","Location","Lead"},0),INDEX(Lists!$B$3:$B$20,ROW()-1),INDEX(Lists!$C$3:$C$146,ROW()-1),INDEX(Lists!$D$3:$D$67,ROW()-1),INDEX(Lists!$E$3:$E$5,ROW()-1),INDEX(Lists!$F$3:$F$12,ROW()-1),INDEX(Lists!$G$3:$G$126,ROW()-1)),"") | K4: =IF(J4="","",SUMPRODUCT(($A$2:$A$636=1)*($G$2:$G$636=J4))) | L4: =IF(J4="","",SUMPRODUCT(($A$2:$A$636=1)*($G$2:$G$636=J4)*(ISNUMBER($B$2:$B$636))*($B$2:$B$636<0.5))) | M4: =IFERROR(L4/K4,"") | N4: =IF(K4="","",M4+K4/100000+ROW()/100000000) | O4: =IFERROR(INDEX($J$2:$J$1001,MATCH(LARGE($N$2:$N$1001,3),$N$2:$N$1001,0)),"") | P4: =IFERROR(INDEX($M$2:$M$1001,MATCH(LARGE($N$2:$N$1001,3),$N$2:$N$1001,0)),"") | Q4: =IFERROR(INDEX($K$2:$K$1001,MATCH(LARGE($N$2:$N$1001,3),$N$2:$N$1001,0)),"") | R4: =IF(A4=1,IFERROR(I4,0)+ROW()/100000000,-1E+99) | S4: =IF(A4=1,IFERROR(Raw_data!$T4,""),"") | T4: =IF(A4=1,IFERROR(Raw_data!$AA4,""),"") | U4: =IF(A4=1,IFERROR(Raw_data!$U4,""),"") | V4: =IF(A4=1,IFERROR(Raw_data!$AB4,""),"")
A5: =--(AND(OR(Dashboard!$B$4="All",Raw_data!$AL5=Dashboard!$B$4),OR(Dashboard!$B$5="All",Raw_data!$AM5=Dashboard!$B$5),OR(Dashboard!$B$6="All",Raw_data!$AN5=Dashboard!$B$6),OR(Dashboard!$B$7="All",Raw_data!$AO5=Dashboard!$B$7),OR(Dashboard!$B$8="All",Raw_data!$AP5=Dashboard!$B$8),OR(Dashboard!$B$9="All",Raw_data!$AQ5=Dashboard!$B$9),OR(Dashboard!$B$10="All",Raw_data!$AF5=Dashboard!$B$10),OR(Raw_data!$F5="",Raw_data!$F5<=TODAY()))) | B5: =IFERROR(IF(Dashboard!$B$3="Weighted",Raw_data!$U5,Raw_data!$T5),"") | C5: =IFERROR(IF(Dashboard!$B$3="Weighted",Raw_data!$AB5,Raw_data!$AA5),"") | D5: =IF(OR(Raw_data!$J5="",Raw_data!$J5<=0,Raw_data!$K5=""),"",IF(Raw_data!$K5>TODAY(),0,DATEDIF(Raw_data!$K5,TODAY(),"M"))) | E5: =--(AND(Raw_data!$AF5="No",OR(Raw_data!$AG5<>"",Raw_data!$AJ5>0,Raw_data!$AK5<>""))) | F5: =--(OR(AND(ISNUMBER(B5),B5<0.5,OR(D5>=24,Raw_data!$I5>0)),Raw_data!$AE5=TRUE)) | G5: =IF(Dashboard!$B$11="Department",Raw_data!$AL5,IF(Dashboard!$B$11="Team",Raw_data!$AM5,IF(Dashboard!$B$11="Unit",Raw_data!$AN5,IF(Dashboard!$B$11="Legal entity",Raw_data!$AO5,IF(Dashboard!$B$11="Location",Raw_data!$AP5,Raw_data!$AQ5))))) | H5: =--(AND(ISNUMBER(B5),B5<0.5)) | I5: =IFERROR(MAX(0,(0.5-B5)*100),0)+IF(D5>=24,20,0)+IF(Raw_data!$I5>0,20,0)+IF(Raw_data!$AE5=TRUE,10,0) | J5: =IFERROR(CHOOSE(MATCH(Dashboard!$B$11,{"Department","Team","Unit","Legal entity","Location","Lead"},0),INDEX(Lists!$B$3:$B$20,ROW()-1),INDEX(Lists!$C$3:$C$146,ROW()-1),INDEX(Lists!$D$3:$D$67,ROW()-1),INDEX(Lists!$E$3:$E$5,ROW()-1),INDEX(Lists!$F$3:$F$12,ROW()-1),INDEX(Lists!$G$3:$G$126,ROW()-1)),"") | K5: =IF(J5="","",SUMPRODUCT(($A$2:$A$636=1)*($G$2:$G$636=J5))) | L5: =IF(J5="","",SUMPRODUCT(($A$2:$A$636=1)*($G$2:$G$636=J5)*(ISNUMBER($B$2:$B$636))*($B$2:$B$636<0.5))) | M5: =IFERROR(L5/K5,"") | N5: =IF(K5="","",M5+K5/100000+ROW()/100000000) | O5: =IFERROR(INDEX($J$2:$J$1001,MATCH(LARGE($N$2:$N$1001,4),$N$2:$N$1001,0)),"") | P5: =IFERROR(INDEX($M$2:$M$1001,MATCH(LARGE($N$2:$N$1001,4),$N$2:$N$1001,0)),"") | Q5: =IFERROR(INDEX($K$2:$K$1001,MATCH(LARGE($N$2:$N$1001,4),$N$2:$N$1001,0)),"") | R5: =IF(A5=1,IFERROR(I5,0)+ROW()/100000000,-1E+99) | S5: =IF(A5=1,IFERROR(Raw_data!$T5,""),"") | T5: =IF(A5=1,IFERROR(Raw_data!$AA5,""),"") | U5: =IF(A5=1,IFERROR(Raw_data!$U5,""),"") | V5: =IF(A5=1,IFERROR(Raw_data!$AB5,""),"")
A6: =--(AND(OR(Dashboard!$B$4="All",Raw_data!$AL6=Dashboard!$B$4),OR(Dashboard!$B$5="All",Raw_data!$AM6=Dashboard!$B$5),OR(Dashboard!$B$6="All",Raw_data!$AN6=Dashboard!$B$6),OR(Dashboard!$B$7="All",Raw_data!$AO6=Dashboard!$B$7),OR(Dashboard!$B$8="All",Raw_data!$AP6=Dashboard!$B$8),OR(Dashboard!$B$9="All",Raw_data!$AQ6=Dashboard!$B$9),OR(Dashboard!$B$10="All",Raw_data!$AF6=Dashboard!$B$10),OR(Raw_data!$F6="",Raw_data!$F6<=TODAY()))) | B6: =IFERROR(IF(Dashboard!$B$3="Weighted",Raw_data!$U6,Raw_data!$T6),"") | C6: =IFERROR(IF(Dashboard!$B$3="Weighted",Raw_data!$AB6,Raw_data!$AA6),"") | D6: =IF(OR(Raw_data!$J6="",Raw_data!$J6<=0,Raw_data!$K6=""),"",IF(Raw_data!$K6>TODAY(),0,DATEDIF(Raw_data!$K6,TODAY(),"M"))) | E6: =--(AND(Raw_data!$AF6="No",OR(Raw_data!$AG6<>"",Raw_data!$AJ6>0,Raw_data!$AK6<>""))) | F6: =--(OR(AND(ISNUMBER(B6),B6<0.5,OR(D6>=24,Raw_data!$I6>0)),Raw_data!$AE6=TRUE)) | G6: =IF(Dashboard!$B$11="Department",Raw_data!$AL6,IF(Dashboard!$B$11="Team",Raw_data!$AM6,IF(Dashboard!$B$11="Unit",Raw_data!$AN6,IF(Dashboard!$B$11="Legal entity",Raw_data!$AO6,IF(Dashboard!$B$11="Location",Raw_data!$AP6,Raw_data!$AQ6))))) | H6: =--(AND(ISNUMBER(B6),B6<0.5)) | I6: =IFERROR(MAX(0,(0.5-B6)*100),0)+IF(D6>=24,20,0)+IF(Raw_data!$I6>0,20,0)+IF(Raw_data!$AE6=TRUE,10,0) | J6: =IFERROR(CHOOSE(MATCH(Dashboard!$B$11,{"Department","Team","Unit","Legal entity","Location","Lead"},0),INDEX(Lists!$B$3:$B$20,ROW()-1),INDEX(Lists!$C$3:$C$146,ROW()-1),INDEX(Lists!$D$3:$D$67,ROW()-1),INDEX(Lists!$E$3:$E$5,ROW()-1),INDEX(Lists!$F$3:$F$12,ROW()-1),INDEX(Lists!$G$3:$G$126,ROW()-1)),"") | K6: =IF(J6="","",SUMPRODUCT(($A$2:$A$636=1)*($G$2:$G$636=J6))) | L6: =IF(J6="","",SUMPRODUCT(($A$2:$A$636=1)*($G$2:$G$636=J6)*(ISNUMBER($B$2:$B$636))*($B$2:$B$636<0.5))) | M6: =IFERROR(L6/K6,"") | N6: =IF(K6="","",M6+K6/100000+ROW()/100000000) | O6: =IFERROR(INDEX($J$2:$J$1001,MATCH(LARGE($N$2:$N$1001,5),$N$2:$N$1001,0)),"") | P6: =IFERROR(INDEX($M$2:$M$1001,MATCH(LARGE($N$2:$N$1001,5),$N$2:$N$1001,0)),"") | Q6: =IFERROR(INDEX($K$2:$K$1001,MATCH(LARGE($N$2:$N$1001,5),$N$2:$N$1001,0)),"") | R6: =IF(A6=1,IFERROR(I6,0)+ROW()/100000000,-1E+99) | S6: =IF(A6=1,IFERROR(Raw_data!$T6,""),"") | T6: =IF(A6=1,IFERROR(Raw_data!$AA6,""),"") | U6: =IF(A6=1,IFERROR(Raw_data!$U6,""),"") | V6: =IF(A6=1,IFERROR(Raw_data!$AB6,""),"")
A7: =--(AND(OR(Dashboard!$B$4="All",Raw_data!$AL7=Dashboard!$B$4),OR(Dashboard!$B$5="All",Raw_data!$AM7=Dashboard!$B$5),OR(Dashboard!$B$6="All",Raw_data!$AN7=Dashboard!$B$6),OR(Dashboard!$B$7="All",Raw_data!$AO7=Dashboard!$B$7),OR(Dashboard!$B$8="All",Raw_data!$AP7=Dashboard!$B$8),OR(Dashboard!$B$9="All",Raw_data!$AQ7=Dashboard!$B$9),OR(Dashboard!$B$10="All",Raw_data!$AF7=Dashboard!$B$10),OR(Raw_data!$F7="",Raw_data!$F7<=TODAY()))) | B7: =IFERROR(IF(Dashboard!$B$3="Weighted",Raw_data!$U7,Raw_data!$T7),"") | C7: =IFERROR(IF(Dashboard!$B$3="Weighted",Raw_data!$AB7,Raw_data!$AA7),"") | D7: =IF(OR(Raw_data!$J7="",Raw_data!$J7<=0,Raw_data!$K7=""),"",IF(Raw_data!$K7>TODAY(),0,DATEDIF(Raw_data!$K7,TODAY(),"M"))) | E7: =--(AND(Raw_data!$AF7="No",OR(Raw_data!$AG7<>"",Raw_data!$AJ7>0,Raw_data!$AK7<>""))) | F7: =--(OR(AND(ISNUMBER(B7),B7<0.5,OR(D7>=24,Raw_data!$I7>0)),Raw_data!$AE7=TRUE)) | G7: =IF(Dashboard!$B$11="Department",Raw_data!$AL7,IF(Dashboard!$B$11="Team",Raw_data!$AM7,IF(Dashboard!$B$11="Unit",Raw_data!$AN7,IF(Dashboard!$B$11="Legal entity",Raw_data!$AO7,IF(Dashboard!$B$11="Location",Raw_data!$AP7,Raw_data!$AQ7))))) | H7: =--(AND(ISNUMBER(B7),B7<0.5)) | I7: =IFERROR(MAX(0,(0.5-B7)*100),0)+IF(D7>=24,20,0)+IF(Raw_data!$I7>0,20,0)+IF(Raw_data!$AE7=TRUE,10,0) | J7: =IFERROR(CHOOSE(MATCH(Dashboard!$B$11,{"Department","Team","Unit","Legal entity","Location","Lead"},0),INDEX(Lists!$B$3:$B$20,ROW()-1),INDEX(Lists!$C$3:$C$146,ROW()-1),INDEX(Lists!$D$3:$D$67,ROW()-1),INDEX(Lists!$E$3:$E$5,ROW()-1),INDEX(Lists!$F$3:$F$12,ROW()-1),INDEX(Lists!$G$3:$G$126,ROW()-1)),"") | K7: =IF(J7="","",SUMPRODUCT(($A$2:$A$636=1)*($G$2:$G$636=J7))) | L7: =IF(J7="","",SUMPRODUCT(($A$2:$A$636=1)*($G$2:$G$636=J7)*(ISNUMBER($B$2:$B$636))*($B$2:$B$636<0.5))) | M7: =IFERROR(L7/K7,"") | N7: =IF(K7="","",M7+K7/100000+ROW()/100000000) | O7: =IFERROR(INDEX($J$2:$J$1001,MATCH(LARGE($N$2:$N$1001,6),$N$2:$N$1001,0)),"") | P7: =IFERROR(INDEX($M$2:$M$1001,MATCH(LARGE($N$2:$N$1001,6),$N$2:$N$1001,0)),"") | Q7: =IFERROR(INDEX($K$2:$K$1001,MATCH(LARGE($N$2:$N$1001,6),$N$2:$N$1001,0)),"") | R7: =IF(A7=1,IFERROR(I7,0)+ROW()/100000000,-1E+99) | S7: =IF(A7=1,IFERROR(Raw_data!$T7,""),"") | T7: =IF(A7=1,IFERROR(Raw_data!$AA7,""),"") | U7: =IF(A7=1,IFERROR(Raw_data!$U7,""),"") | V7: =IF(A7=1,IFERROR(Raw_data!$AB7,""),"")
A8: =--(AND(OR(Dashboard!$B$4="All",Raw_data!$AL8=Dashboard!$B$4),OR(Dashboard!$B$5="All",Raw_data!$AM8=Dashboard!$B$5),OR(Dashboard!$B$6="All",Raw_data!$AN8=Dashboard!$B$6),OR(Dashboard!$B$7="All",Raw_data!$AO8=Dashboard!$B$7),OR(Dashboard!$B$8="All",Raw_data!$AP8=Dashboard!$B$8),OR(Dashboard!$B$9="All",Raw_data!$AQ8=Dashboard!$B$9),OR(Dashboard!$B$10="All",Raw_data!$AF8=Dashboard!$B$10),OR(Raw_data!$F8="",Raw_data!$F8<=TODAY()))) | B8: =IFERROR(IF(Dashboard!$B$3="Weighted",Raw_data!$U8,Raw_data!$T8),"") | C8: =IFERROR(IF(Dashboard!$B$3="Weighted",Raw_data!$AB8,Raw_data!$AA8),"") | D8: =IF(OR(Raw_data!$J8="",Raw_data!$J8<=0,Raw_data!$K8=""),"",IF(Raw_data!$K8>TODAY(),0,DATEDIF(Raw_data!$K8,TODAY(),"M"))) | E8: =--(AND(Raw_data!$AF8="No",OR(Raw_data!$AG8<>"",Raw_data!$AJ8>0,Raw_data!$AK8<>""))) | F8: =--(OR(AND(ISNUMBER(B8),B8<0.5,OR(D8>=24,Raw_data!$I8>0)),Raw_data!$AE8=TRUE)) | G8: =IF(Dashboard!$B$11="Department",Raw_data!$AL8,IF(Dashboard!$B$11="Team",Raw_data!$AM8,IF(Dashboard!$B$11="Unit",Raw_data!$AN8,IF(Dashboard!$B$11="Legal entity",Raw_data!$AO8,IF(Dashboard!$B$11="Location",Raw_data!$AP8,Raw_data!$AQ8))))) | H8: =--(AND(ISNUMBER(B8),B8<0.5)) | I8: =IFERROR(MAX(0,(0.5-B8)*100),0)+IF(D8>=24,20,0)+IF(Raw_data!$I8>0,20,0)+IF(Raw_data!$AE8=TRUE,10,0) | J8: =IFERROR(CHOOSE(MATCH(Dashboard!$B$11,{"Department","Team","Unit","Legal entity","Location","Lead"},0),INDEX(Lists!$B$3:$B$20,ROW()-1),INDEX(Lists!$C$3:$C$146,ROW()-1),INDEX(Lists!$D$3:$D$67,ROW()-1),INDEX(Lists!$E$3:$E$5,ROW()-1),INDEX(Lists!$F$3:$F$12,ROW()-1),INDEX(Lists!$G$3:$G$126,ROW()-1)),"") | K8: =IF(J8="","",SUMPRODUCT(($A$2:$A$636=1)*($G$2:$G$636=J8))) | L8: =IF(J8="","",SUMPRODUCT(($A$2:$A$636=1)*($G$2:$G$636=J8)*(ISNUMBER($B$2:$B$636))*($B$2:$B$636<0.5))) | M8: =IFERROR(L8/K8,"") | N8: =IF(K8="","",M8+K8/100000+ROW()/100000000) | O8: =IFERROR(INDEX($J$2:$J$1001,MATCH(LARGE($N$2:$N$1001,7),$N$2:$N$1001,0)),"") | P8: =IFERROR(INDEX($M$2:$M$1001,MATCH(LARGE($N$2:$N$1001,7),$N$2:$N$1001,0)),"") | Q8: =IFERROR(INDEX($K$2:$K$1001,MATCH(LARGE($N$2:$N$1001,7),$N$2:$N$1001,0)),"") | R8: =IF(A8=1,IFERROR(I8,0)+ROW()/100000000,-1E+99) | S8: =IF(A8=1,IFERROR(Raw_data!$T8,""),"") | T8: =IF(A8=1,IFERROR(Raw_data!$AA8,""),"") | U8: =IF(A8=1,IFERROR(Raw_data!$U8,""),"") | V8: =IF(A8=1,IFERROR(Raw_data!$AB8,""),"")
